Workbook

Sheet Pressupostos
B2: 1. Informação sobre o investimento e pressupostos gerais
B4: Primeiro ano de atividade | F4: 2024
B5: Número de anos até o investimento atingir o ritmo cruzeiro | F5: 2
B7: Contador | F7: 1 | G7: =F7+1 -> 2 | H7: =G7+1 -> 3 | I7: =H7+1 -> 4 | J7: =I7+1 -> 5 | K7: =J7+1 -> 6 | L7: =K7+1 -> 7 | M7: =L7+1 -> 8 | N7: =M7+1 -> 9 | ... T7: =S7+1 -> 15
B8: Indicador de projeção | F8: =IF(F7<=$F$5,1,0) -> 1 | G8: =IF(G7<=$F$5,1,0) -> 1 | H8: =IF(H7<=$F$5,1,0) -> 0 | I8: =IF(I7<=$F$5,1,0) -> 0 | J8: =IF(J7<=$F$5,1,0) -> 0 | K8: =IF(K7<=$F$5,1,0) -> 0 | L8: =IF(L7<=$F$5,1,0) -> 0 | M8: =IF(M7<=$F$5,1,0) -> 0 | ... T8: =IF(T7<=$F$5,1,0) -> 0
B10: Ano | E10: 2023 | F10: =IF(F$8=1,F$4,"") -> 2024 | G10: =IF(G$8=1,F10+1,"") -> 2025 | H10: =IF(H$8=1,G10+1,"") | I10: =IF(I$8=1,H10+1,"") | J10: =IF(J$8=1,I10+1,"") | K10: =IF(K$8=1,J10+1,"") | L10: =IF(L$8=1,K10+1,"") | M10: =IF(M$8=1,L10+1,"") | N10: =IF(N$8=1,M10+1,"") | ... T10: =IF(T$8=1,S10+1,"")
B11: Taxa de inflação | F11: =IF(F10<>"",2%,"") -> 0.02 | G11: =IF(G10<>"",2%,"") -> 0.02 | H11: =IF(H10<>"",2%,"") | I11: =IF(I10<>"",2%,"") | J11: =IF(J10<>"",2%,"") | K11: =IF(K10<>"",2%,"") | L11: =IF(L10<>"",2%,"") | M11: =IF(M10<>"",2%,"") | ... T11: =IF(T10<>"",2%,"")
B12: Iníce de crescimento dos preços | E12: 1 | F12: =IF(F10<>"",E12*(1+F11),"") -> 1.02 | G12: =IF(G10<>"",F12*(1+G11),"") -> 1.0404 | H12: =IF(H10<>"",G12*(1+H11),"") | I12: =IF(I10<>"",H12*(1+I11),"") | J12: =IF(J10<>"",I12*(1+J11),"") | K12: =IF(K10<>"",J12*(1+K11),"") | L12: =IF(L10<>"",K12*(1+L11),"") | M12: =IF(M10<>"",L12*(1+M11),"") | ... T12: =IF(T10<>"",S12*(1+T11),"")
B13: Taxa de crescimento dos salários | F13: =IF(F10<>"",2%,"") -> 0.02 | G13: =IF(G10<>"",2%,"") -> 0.02 | H13: =IF(H10<>"",2%,"") | I13: =IF(I10<>"",2%,"") | J13: =IF(J10<>"",2%,"") | K13: =IF(K10<>"",2%,"") | L13: =IF(L10<>"",2%,"") | M13: =IF(M10<>"",2%,"") | ... T13: =IF(T10<>"",2%,"")
B14: Iníce de crescimento dos salários | F14: 1 | G14: =IF(G12<>"",F14*(1+G13),"") -> 1.02 | H14: =IF(H12<>"",G14*(1+H13),"") | I14: =IF(I12<>"",H14*(1+I13),"") | J14: =IF(J12<>"",I14*(1+J13),"") | K14: =IF(K12<>"",J14*(1+K13),"") | L14: =IF(L12<>"",K14*(1+L13),"") | M14: =IF(M12<>"",L14*(1+M13),"") | N14: =IF(N12<>"",M14*(1+N13),"") | ... T14: =IF(T12<>"",S14*(1+T13),"")
B16: 2. Vendas e serviços prestados
B18: 2.1. Vendas de mercadorias (valor em euros) | F18: =IF(F$8=1,F$4,"") -> 2024 | G18: =IF(G$8=1,F18+1,"") -> 2025 | H18: =IF(H$8=1,G18+1,"") | I18: =IF(I$8=1,H18+1,"") | J18: =IF(J$8=1,I18+1,"") | K18: =IF(K$8=1,J18+1,"") | L18: =IF(L$8=1,K18+1,"") | M18: =IF(M$8=1,L18+1,"") | N18: =IF(N$8=1,M18+1,"") | ... T18: =IF(T$8=1,S18+1,"")
A19: Criar botão para adicionar os elementos que se pretenderem | B19: Mercadoria 1 | C19: Quantidade | F19: 20000 | G19: 25000 | H19: 28000 | I19: 30000 | J19: 35000
C20: Preço de Venda | F20: 10 | G20: 12 | H20: 13 | I20: 13 | J20: 14
C21: Margem Bruta | F21: 0.5 | G21: 0.5 | H21: 0.5 | I21: 0.5 | J21: 0.4
C22: Taxa de IVA | F22: 0.23 | G22: 0.23 | H22: 0.23 | I22: 0.23 | J22: 0.23
B23: Mercadoria 2 | C23: Quantidade | F23: 2000 | G23: 2500 | H23: 2800 | I23: 3000 | J23: 3500
C24: Preço de Venda | F24: 10 | G24: 12 | H24: 13 | I24: 13 | J24: 14
C25: Margem Bruta | F25: 0.5 | G25: 0.5 | H25: 0.5 | I25: 0.5 | J25: 0.4
C26: Taxa de IVA | F26: 0.23 | G26: 0.23 | H26: 0.23 | I26: 0.23 | J26: 0.23
B28: 2.2. Vendas de produtos (valor em euros) | F28: =IF(F$8=1,F$4,"") -> 2024 | G28: =IF(G$8=1,F28+1,"") -> 2025 | H28: =IF(H$8=1,G28+1,"") | I28: =IF(I$8=1,H28+1,"") | J28: =IF(J$8=1,I28+1,"") | K28: =IF(K$8=1,J28+1,"") | L28: =IF(L$8=1,K28+1,"") | M28: =IF(M$8=1,L28+1,"") | N28: =IF(N$8=1,M28+1,"") | ... T28: =IF(T$8=1,S28+1,"")
A29: Criar botão para adicionar os elementos que se pretenderem | B29: Produto 1 | C29: Quantidade | F29: 2000 | G29: 2500 | H29: 2800 | I29: 3000 | J29: 3500
C30: Preço de Venda | F30: 10 | G30: 12 | H30: 13 | I30: 13 | J30: 14
C31: Margem Bruta | F31: 0.5 | G31: 0.5 | H31: 0.5 | I31: 0.5 | J31: 0.4
C32: Taxa de IVA | F32: 0.23 | G32: 0.23 | H32: 0.23 | I32: 0.23 | J32: 0.23
B33: Produto 2 | C33: Quantidade | F33: 2000 | G33: 2500 | H33: 2800 | I33: 3000 | J33: 3500
C34: Preço de Venda | F34: 10 | G34: 12 | H34: 13 | I34: 13 | J34: 14
C35: Margem Bruta | F35: 0.5 | G35: 0.5 | H35: 0.5 | I35: 0.5 | J35: 0.4
C36: Taxa de IVA | F36: 0.23 | G36: 0.23 | H36: 0.23 | I36: 0.23 | J36: 0.23
B38: 2.3. Prestação de serviços (valor em euros) | F38: =IF(F$8=1,F$4,"") -> 2024 | G38: =IF(G$8=1,F38+1,"") -> 2025 | H38: =IF(H$8=1,G38+1,"") | I38: =IF(I$8=1,H38+1,"") | J38: =IF(J$8=1,I38+1,"") | K38: =IF(K$8=1,J38+1,"") | L38: =IF(L$8=1,K38+1,"") | M38: =IF(M$8=1,L38+1,"") | N38: =IF(N$8=1,M38+1,"") | ... T38: =IF(T$8=1,S38+1,"")
A39: Criar botão para adicionar os elementos que se pretenderem | B39: Serviço 1 | C39: Quantidade | F39: 2000 | G39: 2500 | H39: 2800 | I39: 3000 | J39: 3500
C40: Preço de Venda | F40: 10 | G40: 12 | H40: 13 | I40: 13 | J40: 14
C41: Taxa de IVA | F41: 0.23 | G41: 0.23 | H41: 0.23 | I41: 0.23 | J41: 0.23
B42: Serviço 2 | C42: Quantidade | F42: 2000 | G42: 2500 | H42: 2800 | I42: 3000 | J42: 3500
C43: Preço de Venda | F43: 10 | G43: 12 | H43: 13 | I43: 13 | J43: 14
C44: Taxa de IVA | F44: 0.23 | G44: 0.23 | H44: 0.23 | I44: 0.23 | J44: 0.23
B46: 3. Fornecimento e serviços externos (valores em euros)
B48: Descrição | D48: Taxa de IVA | E48: Valor mensal | F48: =IF(F$8=1,F$4,"") -> 2024 | G48: =IF(G$8=1,F48+1,"") -> 2025 | H48: =IF(H$8=1,G48+1,"") | I48: =IF(I$8=1,H48+1,"") | J48: =IF(J$8=1,I48+1,"") | K48: =IF(K$8=1,J48+1,"") | L48: =IF(L$8=1,K48+1,"") | M48: =IF(M$8=1,L48+1,"") | N48: =IF(N$8=1,M48+1,"") | ... T48: =IF(T$8=1,S48+1,"")
B49: Subcontratos
B50: Subcontratos | D50: 0.23 | E50: 100 | F50: =IF(F$8=1,E50*12*(1+F$11),"") -> 1224 | G50: =IF(G$8=1,F50*(1+G$11),"") -> 1248.48 | H50: =IF(H$8=1,G50*(1+H$11),"") | I50: =IF(I$8=1,H50*(1+I$11),"") | J50: =IF(J$8=1,I50*(1+J$11),"") | K50: =IF(K$8=1,J50*(1+K$11),"") | L50: =IF(L$8=1,K50*(1+L$11),"") | M50: =IF(M$8=1,L50*(1+M$11),"") | N50: =IF(N$8=1,M50*(1+N$11),"") | ... T50: =IF(T$8=1,S50*(1+T$11),"")
...

Sheet Sheet1
C3: Descrição | I3: Camião 1
C4: Tipo de Ativo | I4: Ativo fixo tangível
C5: Classe | I5: Equipamento de transporte
C6: Valor de aquisição | I6: 10000
C7: Vida útil | I7: 5
C8: Ano de aquisição | I8: 2023
I9: Depreciações do exercício | O9: Depreciações cumuladas | U9: Ativo líquido
B10: item | C10: Descrição | D10: Tipo de Ativo | E10: Classe | F10: V.aquisição | G10: Vida útil | H10: Ano de aquisição | I10: 2024 | J10: 2025 | K10: 2026 | L10: 2027 | M10: 2028 | N10: 2029 | O10: =I10 -> 2024 | P10: =J10 -> 2025 | Q10: =K10 -> 2026 | R10: =L10 -> 2027 | S10: =M10 -> 2028 | T10: =N10 -> 2029 | U10: =O10 -> 2024 | V10: =P10 -> 2025 | ... Z10: =T10 -> 2029
B11: 1 | C11: Camião 1 | D11: AFT | E11: =I4 -> Ativo fixo tangível | F11: 10000 | G11: 5 | H11: 2023 | I11: =IF(AND(I$10>$H11,I$10-$H11<$G11+1)=TRUE,$F11/$G11) -> 2000 | J11: =IF(AND(J$10>$H11,J$10-$H11<$G11+1)=TRUE,$F11/$G11) -> 2000 | K11: =IF(AND(K$10>$H11,K$10-$H11<$G11+1)=TRUE,$F11/$G11) -> 2000 | L11: =IF(AND(L$10>$H11,L$10-$H11<$G11+1)=TRUE,$F11/$G11) -> 2000 | M11: =IF(AND(M$10>$H11,M$10-$H11<$G11+1)=TRUE,$F11/$G11) -> 2000 | N11: =IF(AND(N$10>$H11,N$10-$H11<$G11+1)=TRUE,$F11/$G11) -> FALSE | O11: =IF(I11=FALSE,0,I11) -> 2000 | P11: =O11+IF(J11=FALSE,0,J11) -> 4000 | Q11: =P11+IF(K11=FALSE,0,K11) -> 6000 | R11: =Q11+IF(L11=FALSE,0,L11) -> 8000 | S11: =R11+IF(M11=FALSE,0,M11) -> 10000 | T11: =S11+IF(N11=FALSE,0,N11) -> 10000 | U11: =IF(I11=FALSE,0,$F11-O11) -> 8000 | V11: =IF(J11=FALSE,0,$F11-P11) -> 6000 | W11: =IF(K11=FALSE,0,$F11-Q11) -> 4000 | X11: =IF(L11=FALSE,0,$F11-R11) -> 2000 | Y11: =IF(M11=FALSE,0,$F11-S11) -> 0 | Z11: =IF(N11=FALSE,0,$F11-T11) -> 0
B12: 2 | C12: Patente | D12: AI | E12: Patentes | F12: 30000 | G12: 3 | H12: 2025 | I12: =IF(AND(I$10>$H12,I$10-$H12<$G12+1)=TRUE,$F12/$G12) -> FALSE | J12: =IF(AND(J$10>$H12,J$10-$H12<$G12+1)=TRUE,$F12/$G12) -> FALSE | K12: =IF(AND(K$10>$H12,K$10-$H12<$G12+1)=TRUE,$F12/$G12) -> 10000 | L12: =IF(AND(L$10>$H12,L$10-$H12<$G12+1)=TRUE,$F12/$G12) -> 10000 | M12: =IF(AND(M$10>$H12,M$10-$H12<$G12+1)=TRUE,$F12/$G12) -> 10000 | N12: =IF(AND(N$10>$H12,N$10-$H12<$G12+1)=TRUE,$F12/$G12) -> FALSE | O12: =N12+IF(I12=FALSE,0,I12) -> 0 | P12: =O12+IF(J12=FALSE,0,J12) -> 0 | Q12: =P12+IF(K12=FALSE,0,K12) -> 10000 | R12: =Q12+IF(L12=FALSE,0,L12) -> 20000 | S12: =R12+IF(M12=FALSE,0,M12) -> 30000 | T12: =S12+IF(N12=FALSE,0,N12) -> 30000 | U12: =IF(I12=FALSE,0,$F12-O12) -> 0 | V12: =IF(J12=FALSE,0,$F12-P12) -> 0 | W12: =IF(K12=FALSE,0,$F12-Q12) -> 20000 | X12: =IF(L12=FALSE,0,$F12-R12) -> 10000 | Y12: =IF(M12=FALSE,0,$F12-S12) -> 0 | Z12: =IF(N12=FALSE,0,$F12-T12) -> 0
B13: 3 | F13: 120000 | G13: 20 | H13: 2023 | I13: =IF(AND(I$10>$H13,I$10-$H13<$G13+1)=TRUE,$F13/$G13) -> 6000 | J13: =IF(AND(J$10>$H13,J$10-$H13<$G13+1)=TRUE,$F13/$G13) -> 6000 | K13: =IF(AND(K$10>$H13,K$10-$H13<$G13+1)=TRUE,$F13/$G13) -> 6000 | L13: =IF(AND(L$10>$H13,L$10-$H13<$G13+1)=TRUE,$F13/$G13) -> 6000 | M13: =IF(AND(M$10>$H13,M$10-$H13<$G13+1)=TRUE,$F13/$G13) -> 6000 | N13: =IF(AND(N$10>$H13,N$10-$H13<$G13+1)=TRUE,$F13/$G13) -> 6000 | O13: =N13+IF(I13=FALSE,0,I13) -> 12000 | P13: =O13+IF(J13=FALSE,0,J13) -> 18000 | Q13: =P13+IF(K13=FALSE,0,K13) -> 24000 | R13: =Q13+IF(L13=FALSE,0,L13) -> 30000 | S13: =R13+IF(M13=FALSE,0,M13) -> 36000 | T13: =S13+IF(N13=FALSE,0,N13) -> 42000 | U13: =IF(I13=FALSE,0,$F13-O13) -> 108000 | V13: =IF(J13=FALSE,0,$F13-P13) -> 102000 | W13: =IF(K13=FALSE,0,$F13-Q13) -> 96000 | X13: =IF(L13=FALSE,0,$F13-R13) -> 90000 | Y13: =IF(M13=FALSE,0,$F13-S13) -> 84000 | Z13: =IF(N13=FALSE,0,$F13-T13) -> 78000
F14: 5000 | G14: 4 | H14: 2023 | I14: =IF(AND(I$10>$H14,I$10-$H14<$G14+1)=TRUE,$F14/$G14) -> 1250 | J14: =IF(AND(J$10>$H14,J$10-$H14<$G14+1)=TRUE,$F14/$G14) -> 1250 | K14: =IF(AND(K$10>$H14,K$10-$H14<$G14+1)=TRUE,$F14/$G14) -> 1250 | L14: =IF(AND(L$10>$H14,L$10-$H14<$G14+1)=TRUE,$F14/$G14) -> 1250 | M14: =IF(AND(M$10>$H14,M$10-$H14<$G14+1)=TRUE,$F14/$G14) -> FALSE | N14: =IF(AND(N$10>$H14,N$10-$H14<$G14+1)=TRUE,$F14/$G14) -> FALSE | O14: =N14+IF(I14=FALSE,0,I14) -> 1250 | P14: =O14+IF(J14=FALSE,0,J14) -> 2500 | Q14: =P14+IF(K14=FALSE,0,K14) -> 3750 | R14: =Q14+IF(L14=FALSE,0,L14) -> 5000 | S14: =R14+IF(M14=FALSE,0,M14) -> 5000 | T14: =S14+IF(N14=FALSE,0,N14) -> 5000 | U14: =IF(I14=FALSE,0,$F14-O14) -> 3750 | V14: =IF(J14=FALSE,0,$F14-P14) -> 2500 | W14: =IF(K14=FALSE,0,$F14-Q14) -> 1250 | X14: =IF(L14=FALSE,0,$F14-R14) -> 0 | Y14: =IF(M14=FALSE,0,$F14-S14) -> 0 | Z14: =IF(N14=FALSE,0,$F14-T14) -> 0

Sheet Compras
B2: COMPRAS DE MERCADORIAS E MATÉRIAS PRIMAS
B3: Descrição | C3: =IF(Pressupostos!F$10<>"",Pressupostos!F$10,"") -> 2024 | D3: =IF(Pressupostos!G$10<>"",Pressupostos!G$10,"") -> 2025 | E3: =IF(Pressupostos!H$10<>"",Pressupostos!H$10,"") | F3: =IF(Pressupostos!I$10<>"",Pressupostos!I$10,"") | G3: =IF(Pressupostos!J$10<>"",Pressupostos!J$10,"") | H3: =IF(Pressupostos!K$10<>"",Pressupostos!K$10,"") | I3: =IF(Pressupostos!L$10<>"",Pressupostos!L$10,"") | J3: =IF(Pressupostos!M$10<>"",Pressupostos!M$10,"") | ... Q3: =IF(Pressupostos!T$10<>"",Pressupostos!T$10,"")
B4: Custo das mercadorias vendidas:
B5: =+Pressupostos!B19 -> Mercadoria 1 | C5: =IF(Pressupostos!F$10<>"",Pressupostos!F19*Pressupostos!F20*(1-Pressupostos!F21),"") -> 100000 | D5: =IF(Pressupostos!G$10<>"",Pressupostos!G19*Pressupostos!G20*(1-Pressupostos!G21),"") -> 150000 | E5: =IF(Pressupostos!H$10<>"",Pressupostos!H19*Pressupostos!H20*(1-Pressupostos!H21),"") | F5: =IF(Pressupostos!I$10<>"",Pressupostos!I19*Pressupostos!I20*(1-Pressupostos!I21),"") | G5: =IF(Pressupostos!J$10<>"",Pressupostos!J19*Pressupostos!J20*(1-Pressupostos!J21),"") | H5: =IF(Pressupostos!K$10<>"",Pressupostos!K19*Pressupostos!K20*(1-Pressupostos!K21),"") | I5: =IF(Pressupostos!L$10<>"",Pressupostos!L19*Pressupostos!L20*(1-Pressupostos!L21),"") | J5: =IF(Pressupostos!M$10<>"",Pressupostos!M19*Pressupostos!M20*(1-Pressupostos!M21),"") | ... Q5: =IF(Pressupostos!T$10<>"",Pressupostos!T19*Pressupostos!T20*(1-Pressupostos!T21),"")
B6: =+Pressupostos!B23 -> Mercadoria 2 | C6: =IF(Pressupostos!F$10<>"",Pressupostos!F23*Pressupostos!F24*(1-Pressupostos!F25),"") -> 10000 | D6: =IF(Pressupostos!G$10<>"",Pressupostos!G23*Pressupostos!G24*(1-Pressupostos!G25),"") -> 15000 | E6: =IF(Pressupostos!H$10<>"",Pressupostos!H23*Pressupostos!H24*(1-Pressupostos!H25),"") | F6: =IF(Pressupostos!I$10<>"",Pressupostos!I23*Pressupostos!I24*(1-Pressupostos!I25),"") | G6: =IF(Pressupostos!J$10<>"",Pressupostos!J23*Pressupostos!J24*(1-Pressupostos!J25),"") | H6: =IF(Pressupostos!K$10<>"",Pressupostos!K23*Pressupostos!K24*(1-Pressupostos!K25),"") | I6: =IF(Pressupostos!L$10<>"",Pressupostos!L23*Pressupostos!L24*(1-Pressupostos!L25),"") | J6: =IF(Pressupostos!M$10<>"",Pressupostos!M23*Pressupostos!M24*(1-Pressupostos!M25),"") | ... Q6: =IF(Pressupostos!T$10<>"",Pressupostos!T23*Pressupostos!T24*(1-Pressupostos!T25),"")
B7: Custo das matérias consumidas:
B8: =_xlfn.CONCAT("Matérias-primas do ",Pressupostos!B29) -> Matérias-primas do Produto 1 | C8: =IF(Pressupostos!F$10<>"",Pressupostos!F29*Pressupostos!F30*(1-Pressupostos!F31),"") -> 10000 | D8: =IF(Pressupostos!G$10<>"",Pressupostos!G29*Pressupostos!G30*(1-Pressupostos!G31),"") -> 15000 | E8: =IF(Pressupostos!H$10<>"",Pressupostos!H29*Pressupostos!H30*(1-Pressupostos!H31),"") | F8: =IF(Pressupostos!I$10<>"",Pressupostos!I29*Pressupostos!I30*(1-Pressupostos!I31),"") | G8: =IF(Pressupostos!J$10<>"",Pressupostos!J29*Pressupostos!J30*(1-Pressupostos!J31),"") | H8: =IF(Pressupostos!K$10<>"",Pressupostos!K29*Pressupostos!K30*(1-Pressupostos!K31),"") | I8: =IF(Pressupostos!L$10<>"",Pressupostos!L29*Pressupostos!L30*(1-Pressupostos!L31),"") | J8: =IF(Pressupostos!M$10<>"",Pressupostos!M29*Pressupostos!M30*(1-Pressupostos!M31),"") | ... Q8: =IF(Pressupostos!T$10<>"",Pressupostos!T29*Pressupostos!T30*(1-Pressupostos!T31),"")
B9: =_xlfn.CONCAT("Matérias-primas do ",Pressupostos!B33) -> Matérias-primas do Produto 2 | C9: =IF(Pressupostos!F$10<>"",Pressupostos!F33*Pressupostos!F34*(1-Pressupostos!F35),"") -> 10000 | D9: =IF(Pressupostos!G$10<>"",Pressupostos!G33*Pressupostos!G34*(1-Pressupostos!G35),"") -> 15000 | E9: =IF(Pressupostos!H$10<>"",Pressupostos!H33*Pressupostos!H34*(1-Pressupostos!H35),"") | F9: =IF(Pressupostos!I$10<>"",Pressupostos!I33*Pressupostos!I34*(1-Pressupostos!I35),"") | G9: =IF(Pressupostos!J$10<>"",Pressupostos!J33*Pressupostos!J34*(1-Pressupostos!J35),"") | H9: =IF(Pressupostos!K$10<>"",Pressupostos!K33*Pressupostos!K34*(1-Pressupostos!K35),"") | I9: =IF(Pressupostos!L$10<>"",Pressupostos!L33*Pressupostos!L34*(1-Pressupostos!L35),"") | J9: =IF(Pressupostos!M$10<>"",Pressupostos!M33*Pressupostos!M34*(1-Pressupostos!M35),"") | ... Q9: =IF(Pressupostos!T$10<>"",Pressupostos!T33*Pressupostos!T34*(1-Pressupostos!T35),"")
B10: Stock final de mercadorias:
B11: =B5 -> Mercadoria 1 | C11: =IF(Pressupostos!F$10<>"",C5/12*Pressupostos!$D$125,"") -> 4166.6667 | D11: =IF(Pressupostos!G$10<>"",D5/12*Pressupostos!$D$125,"") -> 6250 | E11: =IF(Pressupostos!H$10<>"",E5/12*Pressupostos!$D$125,"") | F11: =IF(Pressupostos!I$10<>"",F5/12*Pressupostos!$D$125,"") | G11: =IF(Pressupostos!J$10<>"",G5/12*Pressupostos!$D$125,"") | H11: =IF(Pressupostos!K$10<>"",H5/12*Pressupostos!$D$125,"") | I11: =IF(Pressupostos!L$10<>"",I5/12*Pressupostos!$D$125,"") | J11: =IF(Pressupostos!M$10<>"",J5/12*Pressupostos!$D$125,"") | ... Q11: =IF(Pressupostos!T$10<>"",Q5/12*Pressupostos!$D$125,"")
B12: =B6 -> Mercadoria 2 | C12: =IF(Pressupostos!F$10<>"",C6/12*Pressupostos!$D$125,"") -> 416.66667 | D12: =IF(Pressupostos!G$10<>"",D6/12*Pressupostos!$D$125,"") -> 625 | E12: =IF(Pressupostos!H$10<>"",E6/12*Pressupostos!$D$125,"") | F12: =IF(Pressupostos!I$10<>"",F6/12*Pressupostos!$D$125,"") | G12: =IF(Pressupostos!J$10<>"",G6/12*Pressupostos!$D$125,"") | H12: =IF(Pressupostos!K$10<>"",H6/12*Pressupostos!$D$125,"") | I12: =IF(Pressupostos!L$10<>"",I6/12*Pressupostos!$D$125,"") | J12: =IF(Pressupostos!M$10<>"",J6/12*Pressupostos!$D$125,"") | ... Q12: =IF(Pressupostos!T$10<>"",Q6/12*Pressupostos!$D$125,"")
B13: Stock final de matérias.primas:
B14: =+B8 -> Matérias-primas do Produto 1 | C14: =IF(Pressupostos!F$10<>"",C8/12*Pressupostos!$D$126,"") -> 416.66667 | D14: =IF(Pressupostos!G$10<>"",D8/12*Pressupostos!$D$126,"") -> 625 | E14: =IF(Pressupostos!H$10<>"",E8/12*Pressupostos!$D$126,"") | F14: =IF(Pressupostos!I$10<>"",F8/12*Pressupostos!$D$126,"") | G14: =IF(Pressupostos!J$10<>"",G8/12*Pressupostos!$D$126,"") | H14: =IF(Pressupostos!K$10<>"",H8/12*Pressupostos!$D$126,"") | I14: =IF(Pressupostos!L$10<>"",I8/12*Pressupostos!$D$126,"") | J14: =IF(Pressupostos!M$10<>"",J8/12*Pressupostos!$D$126,"") | ... Q14: =IF(Pressupostos!T$10<>"",Q8/12*Pressupostos!$D$126,"")
B15: =+B9 -> Matérias-primas do Produto 2 | C15: =IF(Pressupostos!F$10<>"",C9/12*Pressupostos!$D$126,"") -> 416.66667 | D15: =IF(Pressupostos!G$10<>"",D9/12*Pressupostos!$D$126,"") -> 625 | E15: =IF(Pressupostos!H$10<>"",E9/12*Pressupostos!$D$126,"") | F15: =IF(Pressupostos!I$10<>"",F9/12*Pressupostos!$D$126,"") | G15: =IF(Pressupostos!J$10<>"",G9/12*Pressupostos!$D$126,"") | H15: =IF(Pressupostos!K$10<>"",H9/12*Pressupostos!$D$126,"") | I15: =IF(Pressupostos!L$10<>"",I9/12*Pressupostos!$D$126,"") | J15: =IF(Pressupostos!M$10<>"",J9/12*Pressupostos!$D$126,"") | ... Q15: =IF(Pressupostos!T$10<>"",Q9/12*Pressupostos!$D$126,"")
B16: Stock inicial de mercadorias:
B17: =B11 -> Mercadoria 1 | D17: =IF(Pressupostos!G$10<>"",C11,"") -> 4166.6667 | E17: =IF(Pressupostos!H$10<>"",D11,"") | F17: =IF(Pressupostos!I$10<>"",E11,"") | G17: =IF(Pressupostos!J$10<>"",F11,"") | H17: =IF(Pressupostos!K$10<>"",G11,"") | I17: =IF(Pressupostos!L$10<>"",H11,"") | J17: =IF(Pressupostos!M$10<>"",I11,"") | K17: =IF(Pressupostos!N$10<>"",J11,"") | ... Q17: =IF(Pressupostos!T$10<>"",P11,"")
B18: =B12 -> Mercadoria 2 | D18: =IF(Pressupostos!G$10<>"",C12,"") -> 416.66667 | E18: =IF(Pressupostos!H$10<>"",D12,"") | F18: =IF(Pressupostos!I$10<>"",E12,"") | G18: =IF(Pressupostos!J$10<>"",F12,"") | H18: =IF(Pressupostos!K$10<>"",G12,"") | I18: =IF(Pressupostos!L$10<>"",H12,"") | J18: =IF(Pressupostos!M$10<>"",I12,"") | K18: =IF(Pressupostos!N$10<>"",J12,"") | ... Q18: =IF(Pressupostos!T$10<>"",P12,"")
B19: Stock inicial de matérias.primas:
B20: =+B14 -> Matérias-primas do Produto 1 | D20: =IF(Pressupostos!G$10<>"",C14,"") -> 416.66667 | E20: =IF(Pressupostos!H$10<>"",D14,"") | F20: =IF(Pressupostos!I$10<>"",E14,"") | G20: =IF(Pressupostos!J$10<>"",F14,"") | H20: =IF(Pressupostos!K$10<>"",G14,"") | I20: =IF(Pressupostos!L$10<>"",H14,"") | J20: =IF(Pressupostos!M$10<>"",I14,"") | K20: =IF(Pressupostos!N$10<>"",J14,"") | ... Q20: =IF(Pressupostos!T$10<>"",P14,"")
B21: =+B15 -> Matérias-primas do Produto 2 | D21: =IF(Pressupostos!G$10<>"",C15,"") -> 416.66667 | E21: =IF(Pressupostos!H$10<>"",D15,"") | F21: =IF(Pressupostos!I$10<>"",E15,"") | G21: =IF(Pressupostos!J$10<>"",F15,"") | H21: =IF(Pressupostos!K$10<>"",G15,"") | I21: =IF(Pressupostos!L$10<>"",H15,"") | J21: =IF(Pressupostos!M$10<>"",I15,"") | K21: =IF(Pressupostos!N$10<>"",J15,"") | ... Q21: =IF(Pressupostos!T$10<>"",P15,"")
B22: Compras de mercadorias:
B23: =B17 -> Mercadoria 1 | C23: =IF(Pressupostos!F$10<>"",C5+C11-C17,"") -> 104166.67 | D23: =IF(Pressupostos!G$10<>"",D5+D11-D17,"") -> 152083.33 | E23: =IF(Pressupostos!H$10<>"",E5+E11-E17,"") | F23: =IF(Pressupostos!I$10<>"",F5+F11-F17,"") | G23: =IF(Pressupostos!J$10<>"",G5+G11-G17,"") | H23: =IF(Pressupostos!K$10<>"",H5+H11-H17,"") | I23: =IF(Pressupostos!L$10<>"",I5+I11-I17,"") | J23: =IF(Pressupostos!M$10<>"",J5+J11-J17,"") | ... Q23: =IF(Pressupostos!T$10<>"",Q5+Q11-Q17,"")
B24: =B18 -> Mercadoria 2 | C24: =IF(Pressupostos!F$10<>"",C6+C12-C18,"") -> 10416.667 | D24: =IF(Pressupostos!G$10<>"",D6+D12-D18,"") -> 15208.333 | E24: =IF(Pressupostos!H$10<>"",E6+E12-E18,"") | F24: =IF(Pressupostos!I$10<>"",F6+F12-F18,"") | G24: =IF(Pressupostos!J$10<>"",G6+G12-G18,"") | H24: =IF(Pressupostos!K$10<>"",H6+H12-H18,"") | I24: =IF(Pressupostos!L$10<>"",I6+I12-I18,"") | J24: =IF(Pressupostos!M$10<>"",J6+J12-J18,"") | ... Q24: =IF(Pressupostos!T$10<>"",Q6+Q12-Q18,"")
B25: Compra de matérias-primas:
B26: =B20 -> Matérias-primas do Produto 1 | C26: =IF(Pressupostos!F$10<>"",C8+C14-C20,"") -> 10416.667 | D26: =IF(Pressupostos!G$10<>"",D8+D14-D20,"") -> 15208.333 | E26: =IF(Pressupostos!H$10<>"",E8+E14-E20,"") | F26: =IF(Pressupostos!I$10<>"",F8+F14-F20,"") | G26: =IF(Pressupostos!J$10<>"",G8+G14-G20,"") | H26: =IF(Pressupostos!K$10<>"",H8+H14-H20,"") | I26: =IF(Pressupostos!L$10<>"",I8+I14-I20,"") | J26: =IF(Pressupostos!M$10<>"",J8+J14-J20,"") | ... Q26: =IF(Pressupostos!T$10<>"",Q8+Q14-Q20,"")
B27: =B21 -> Matérias-primas do Produto 2 | C27: =IF(Pressupostos!F$10<>"",C9+C15-C21,"") -> 10416.667 | D27: =IF(Pressupostos!G$10<>"",D9+D15-D21,"") -> 15208.333 | E27: =IF(Pressupostos!H$10<>"",E9+E15-E21,"") | F27: =IF(Pressupostos!I$10<>"",F9+F15-F21,"") | G27: =IF(Pressupostos!J$10<>"",G9+G15-G21,"") | H27: =IF(Pressupostos!K$10<>"",H9+H15-H21,"") | I27: =IF(Pressupostos!L$10<>"",I9+I15-I21,"") | J27: =IF(Pressupostos!M$10<>"",J9+J15-J21,"") | ... Q27: =IF(Pressupostos!T$10<>"",Q9+Q15-Q21,"")
B30: VARIAÇÃO DOS INVENTÁRIOS DA PRODUÇÃO
B31: Descrição | C31: =IF(Pressupostos!F$10<>"",Pressupostos!F$10,"") -> 2024 | D31: =IF(Pressupostos!G$10<>"",Pressupostos!G$10,"") -> 2025 | E31: =IF(Pressupostos!H$10<>"",Pressupostos!H$10,"") | F31: =IF(Pressupostos!I$10<>"",Pressupostos!I$10,"") | G31: =IF(Pressupostos!J$10<>"",Pressupostos!J$10,"") | H31: =IF(Pressupostos!K$10<>"",Pressupostos!K$10,"") | I31: =IF(Pressupostos!L$10<>"",Pressupostos!L$10,"") | J31: =IF(Pressupostos!M$10<>"",Pressupostos!M$10,"") | ... Q31: =IF(Pressupostos!T$10<>"",Pressupostos!T$10,"")
B32: Variação dos inventários da produção
B33: Stock inicial de produtos acabados | D33: =IF(Pressupostos!G$10<>"",C34,"") -> 12500 | E33: =IF(Pressupostos!H$10<>"",D34,"") | F33: =IF(Pressupostos!I$10<>"",E34,"") | G33: =IF(Pressupostos!J$10<>"",F34,"") | H33: =IF(Pressupostos!K$10<>"",G34,"") | I33: =IF(Pressupostos!L$10<>"",H34,"") | J33: =IF(Pressupostos!M$10<>"",I34,"") | K33: =IF(Pressupostos!N$10<>"",J34,"") | ... Q33: =IF(Pressupostos!T$10<>"",P34,"")
B34: Stock final de produtos acabados | C34: =IF(Pressupostos!F$10<>"",DR!C4/12*Pressupostos!$D$127,"") -> 12500 | D34: =IF(Pressupostos!G$10<>"",DR!D4/12*Pressupostos!$D$127,"") -> 18750 | E34: =IF(Pressupostos!H$10<>"",DR!E4/12*Pressupostos!$D$127,"") | F34: =IF(Pressupostos!I$10<>"",DR!F4/12*Pressupostos!$D$127,"") | G34: =IF(Pressupostos!J$10<>"",DR!G4/12*Pressupostos!$D$127,"") | H34: =IF(Pressupostos!K$10<>"",DR!H4/12*Pressupostos!$D$127,"") | I34: =IF(Pressupostos!L$10<>"",DR!I4/12*Pressupostos!$D$127,"") | J34: =IF(Pressupostos!M$10<>"",DR!J4/12*Pressupostos!$D$127,"") | ... Q34: =IF(Pressupostos!T$10<>"",DR!Q4/12*Pressupostos!$D$127,"")
B35: Variação dos inventários da produção | C35: =IF(Pressupostos!F$10<>"",C34-C33,"") -> 12500 | D35: =IF(Pressupostos!G$10<>"",D34-D33,"") -> 6250 | E35: =IF(Pressupostos!H$10<>"",E34-E33,"") | F35: =IF(Pressupostos!I$10<>"",F34-F33,"") | G35: =IF(Pressupostos!J$10<>"",G34-G33,"") | H35: =IF(Pressupostos!K$10<>"",H34-H33,"") | I35: =IF(Pressupostos!L$10<>"",I34-I33,"") | J35: =IF(Pressupostos!M$10<>"",J34-J33,"") | ... Q35: =IF(Pressupostos!T$10<>"",Q34-Q33,"")

Sheet DR
B2: DEMONSTRAÇÃO DE RESULTADOS PREVISIONAIS
B3: Descrição | C3: =IF(Pressupostos!F10<>"",Pressupostos!F10,"") -> 2024 | D3: =IF(Pressupostos!G10<>"",Pressupostos!G10,"") -> 2025 | E3: =IF(Pressupostos!H10<>"",Pressupostos!H10,"") | F3: =IF(Pressupostos!I10<>"",Pressupostos!I10,"") | G3: =IF(Pressupostos!J10<>"",Pressupostos!J10,"") | H3: =IF(Pressupostos!K10<>"",Pressupostos!K10,"") | I3: =IF(Pressupostos!L10<>"",Pressupostos!L10,"") | J3: =IF(Pressupostos!M10<>"",Pressupostos!M10,"") | ... Q3: =IF(Pressupostos!T10<>"",Pressupostos!T10,"")
B4: Vendas e prestação de serviços | C4: =IF(Pressupostos!F$8=1,Pressupostos!F19*Pressupostos!F20+Pressupostos!F23*Pressupostos!F24+Pressupostos!F29*Pressupostos!F30+Pressupostos!F33*Pressupostos!F34+Pressupostos!F39*Pressupostos!F40+Pressupostos!F42*Pressupostos!F43,"") -> 300000 | D4: =IF(Pressupostos!G$8=1,Pressupostos!G19*Pressupostos!G20+Pressupostos!G23*Pressupostos!G24+Pressupostos!G29*Pressupostos!G30+Pressupostos!G33*Pressupostos!G34+Pressupostos!G39*Pressupostos!G40+Pressupostos!G42*Pressupostos!G43,"") -> 450000 | E4: =IF(Pressupostos!H$8=1,Pressupostos!H19*Pressupostos!H20+Pressupostos!H23*Pressupostos!H24+Pressupostos!H29*Pressupostos!H30+Pressupostos!H33*Pressupostos!H34+Pressupostos!H39*Pressupostos!H40+Pressupostos!H42*Pressupostos!H43,"") | F4: =IF(Pressupostos!I$8=1,Pressupostos!I19*Pressupostos!I20+Pressupostos!I23*Pressupostos!I24+Pressupostos!I29*Pressupostos!I30+Pressupostos!I33*Pressupostos!I34+Pressupostos!I39*Pressupostos!I40+Pressupostos!I42*Pressupostos!I43,"") | G4: =IF(Pressupostos!J$8=1,Pressupostos!J19*Pressupostos!J20+Pressupostos!J23*Pressupostos!J24+Pressupostos!J29*Pressupostos!J30+Pressupostos!J33*Pressupostos!J34+Pressupostos!J39*Pressupostos!J40+Pressupostos!J42*Pressupostos!J43,"") | H4: =IF(Pressupostos!K$8=1,Pressupostos!K19*Pressupostos!K20+Pressupostos!K23*Pressupostos!K24+Pressupostos!K29+Pressupostos!K30+Pressupostos!K33*Pressupostos!K34+Pressupostos!K39*Pressupostos!K40+Pressupostos!K42*Pressupostos!K43,"") | I4: =IF(Pressupostos!L$8=1,Pressupostos!L19*Pressupostos!L20+Pressupostos!L23*Pressupostos!L24+Pressupostos!L29+Pressupostos!L30+Pressupostos!L33*Pressupostos!L34+Pressupostos!L39*Pressupostos!L40+Pressupostos!L42*Pressupostos!L43,"") | J4: =IF(Pressupostos!M$8=1,Pressupostos!M19*Pressupostos!M20+Pressupostos!M23*Pressupostos!M24+Pressupostos!M29+Pressupostos!M30+Pressupostos!M33*Pressupostos!M34+Pressupostos!M39*Pressupostos!M40+Pressupostos!M42*Pressupostos!M43,"") | K4: =IF(Pressupostos!N$8=1,Pressupostos!N19*Pressupostos!N20+Pressupostos!N23*Pressupostos!N24+Pressupostos!N29+Pressupostos!N30+Pressupostos!N33*Pressupostos!N34+Pressupostos!N39*Pressupostos!N40+Pressupostos!N42*Pressupostos!N43,"") | L4: =IF(Pressupostos!O$8=1,Pressupostos!O19*Pressupostos!O20+Pressupostos!O23*Pressupostos!O24+Pressupostos!O29+Pressupostos!O30+Pressupostos!O33*Pressupostos!O34+Pressupostos!O39*Pressupostos!O40+Pressupostos!O42*Pressupostos!O43,"") | M4: =IF(Pressupostos!P$8=1,Pressupostos!P19*Pressupostos!P20+Pressupostos!P23*Pressupostos!P24+Pressupostos!P29+Pressupostos!P30+Pressupostos!P33*Pressupostos!P34+Pressupostos!P39*Pressupostos!P40+Pressupostos!P42*Pressupostos!P43,"") | N4: =IF(Pressupostos!Q$8=1,Pressupostos!Q19*Pressupostos!Q20+Pressupostos!Q23*Pressupostos!Q24+Pressupostos!Q29+Pressupostos!Q30+Pressupostos!Q33*Pressupostos!Q34+Pressupostos!Q39*Pressupostos!Q40+Pressupostos!Q42*Pressupostos!Q43,"") | O4: =IF(Pressupostos!R$8=1,Pressupostos!R19*Pressupostos!R20+Pressupostos!R23*Pressupostos!R24+Pressupostos!R29+Pressupostos!R30+Pressupostos!R33*Pressupostos!R34+Pressupostos!R39*Pressupostos!R40+Pressupostos!R42*Pressupostos!R43,"") | ... Q4: =IF(Pressupostos!T$8=1,Pressupostos!T19*Pressupostos!T20+Pressupostos!T23*Pressupostos!T24+Pressupostos!T29+Pressupostos!T30+Pressupostos!T33*Pressupostos!T34+Pressupostos!T39*Pressupostos!T40+Pressupostos!T42*Pressupostos!T43,"")
B5: Variação nos inventários da produção | C5: =Compras!C35 -> 12500 | D5: =Compras!D35 -> 6250 | E5: =Compras!E35 | F5: =Compras!F35 | G5: =Compras!G35 | H5: =Compras!H35 | I5: =Compras!I35 | J5: =Compras!J35 | ... Q5: =Compras!Q35
B6: Custo das mercadorias vendidas e matérias consumidas | C6: =IF(Pressupostos!F$8=1,-SUM(Compras!C5:C6)-SUM(Compras!C8:C9),"") -> -130000 | D6: =IF(Pressupostos!G$8=1,-SUM(Compras!D5:D6)-SUM(Compras!D8:D9),"") -> -195000 | E6: =IF(Pressupostos!H$8=1,-SUM(Compras!E5:E6)-SUM(Compras!E8:E9),"") | F6: =IF(Pressupostos!I$8=1,-SUM(Compras!F5:F6)-SUM(Compras!F8:F9),"") | G6: =IF(Pressupostos!J$8=1,-SUM(Compras!G5:G6)-SUM(Compras!G8:G9),"") | H6: =IF(Pressupostos!K$8=1,-SUM(Compras!H5:H6)-SUM(Compras!H8:H9),"") | I6: =IF(Pressupostos!L$8=1,-SUM(Compras!I5:I6)-SUM(Compras!I8:I9),"") | J6: =IF(Pressupostos!M$8=1,-SUM(Compras!J5:J6)-SUM(Compras!J8:J9),"") | ... Q6: =IF(Pressupostos!T$8=1,-SUM(Compras!Q5:Q6)-SUM(Compras!Q8:Q9),"")
B7: Fornecimentos e serviços externos | C7: =IF(Pressupostos!F$8=1,-E83-SUM(Pressupostos!F52:F57)-SUM(Pressupostos!F59:F62)-SUM(Pressupostos!F64:F66)-SUM(Pressupostos!F68:F70)-SUM(Pressupostos!F72:F78)-Pressupostos!F80,"") -> -18041.76 | D7: =IF(Pressupostos!G$8=1,-F83-SUM(Pressupostos!G52:G57)-SUM(Pressupostos!G59:G62)-SUM(Pressupostos!G64:G66)-SUM(Pressupostos!G68:G70)-SUM(Pressupostos!G72:G78)-Pressupostos!G80,"") -> -18402.595 | E7: =IF(Pressupostos!H$8=1,-G83-SUM(Pressupostos!H52:H57)-SUM(Pressupostos!H59:H62)-SUM(Pressupostos!H64:H66)-SUM(Pressupostos!H68:H70)-SUM(Pressupostos!H72:H78)-Pressupostos!H80,"") | F7: =IF(Pressupostos!I$8=1,-H83-SUM(Pressupostos!I52:I57)-SUM(Pressupostos!I59:I62)-SUM(Pressupostos!I64:I66)-SUM(Pressupostos!I68:I70)-SUM(Pressupostos!I72:I78)-Pressupostos!I80,"") | G7: =IF(Pressupostos!J$8=1,-I83-SUM(Pressupostos!J52:J57)-SUM(Pressupostos!J59:J62)-SUM(Pressupostos!J64:J66)-SUM(Pressupostos!J68:J70)-SUM(Pressupostos!J72:J78)-Pressupostos!J80,"") | H7: =IF(Pressupostos!K$8=1,-J83-SUM(Pressupostos!K52:K57)-SUM(Pressupostos!K59:K62)-SUM(Pressupostos!K64:K66)-SUM(Pressupostos!K68:K70)-SUM(Pressupostos!K72:K78)-Pressupostos!K80,"") | I7: =IF(Pressupostos!L$8=1,-K83-SUM(Pressupostos!L52:L57)-SUM(Pressupostos!L59:L62)-SUM(Pressupostos!L64:L66)-SUM(Pressupostos!L68:L70)-SUM(Pressupostos!L72:L78)-Pressupostos!L80,"") | J7: =IF(Pressupostos!M$8=1,-L83-SUM(Pressupostos!M52:M57)-SUM(Pressupostos!M59:M62)-SUM(Pressupostos!M64:M66)-SUM(Pressupostos!M68:M70)-SUM(Pressupostos!M72:M78)-Pressupostos!M80,"") | ... Q7: =IF(Pressupostos!T$8=1,-S83-SUM(Pressupostos!T52:T57)-SUM(Pressupostos!T59:T62)-SUM(Pressupostos!T64:T66)-SUM(Pressupostos!T68:T70)-SUM(Pressupostos!T72:T78)-Pressupostos!T80,"")
B8: Gastos com pessoal | C8: =IF(Pressupostos!F$8=1,-SUM(Pressupostos!F96:F98)*(1+Pressupostos!$D$118)-Pressupostos!F101-Pressupostos!F104,"") -> -63805.5 | D8: =IF(Pressupostos!G$8=1,-SUM(Pressupostos!G96:G98)*(1+Pressupostos!$D$118)-Pressupostos!G101-Pressupostos!G104,"") -> -65081.61 | E8: =IF(Pressupostos!H$8=1,-SUM(Pressupostos!H96:H98)*(1+Pressupostos!$D$118)-Pressupostos!H101-Pressupostos!H104,"") | F8: =IF(Pressupostos!I$8=1,-SUM(Pressupostos!I96:I98)*(1+Pressupostos!$D$118)-Pressupostos!I101-Pressupostos!I104,"") | G8: =IF(Pressupostos!J$8=1,-SUM(Pressupostos!J96:J98)*(1+Pressupostos!$D$118)-Pressupostos!J101-Pressupostos!J104,"") | H8: =IF(Pressupostos!K$8=1,-SUM(Pressupostos!K96:K98)*(1+Pressupostos!$D$118)-Pressupostos!K101-Pressupostos!K104,"") | I8: =IF(Pressupostos!L$8=1,-SUM(Pressupostos!L96:L98)*(1+Pressupostos!$D$118)-Pressupostos!L101-Pressupostos!L104,"") | J8: =IF(Pressupostos!M$8=1,-SUM(Pressupostos!M96:M98)*(1+Pressupostos!$D$118)-Pressupostos!M101-Pressupostos!M104,"") | ... Q8: =IF(Pressupostos!T$8=1,-SUM(Pressupostos!T96:T98)*(1+Pressupostos!$D$118)-Pressupostos!T101-Pressupostos!T104,"")
B9: Outros rendimentos e gastos | C9: =IF(Pressupostos!F$8=1,-Pressupostos!$D$109*DR!C4+Compras!C35,"") -> 9500 | D9: =IF(Pressupostos!G$8=1,-Pressupostos!$D$109*DR!D4+Compras!D35,"") -> 1750 | E9: =IF(Pressupostos!H$8=1,-Pressupostos!$D$109*DR!E4+Compras!E35,"") | F9: =IF(Pressupostos!I$8=1,-Pressupostos!$D$109*DR!F4+Compras!F35,"") | G9: =IF(Pressupostos!J$8=1,-Pressupostos!$D$109*DR!G4+Compras!G35,"") | H9: =IF(Pressupostos!K$8=1,-Pressupostos!$D$109*DR!H4+Compras!H35,"") | I9: =IF(Pressupostos!L$8=1,-Pressupostos!$D$109*DR!I4+Compras!I35,"") | J9: =IF(Pressupostos!M$8=1,-Pressupostos!$D$109*DR!J4+Compras!J35,"") | ... Q9: =IF(Pressupostos!T$8=1,-Pressupostos!$D$109*DR!Q4+Compras!Q35,"")
B10: EBITDA | C10: =IF(Pressupostos!F$8=1,SUM(C4:C9),"") -> 110152.74 | D10: =IF(Pressupostos!G$8=1,SUM(D4:D9),"") -> 179515.79 | E10: =IF(Pressupostos!H$8=1,SUM(E4:E9),"") | F10: =IF(Pressupostos!I$8=1,SUM(F4:F9),"") | G10: =IF(Pressupostos!J$8=1,SUM(G4:G9),"") | H10: =IF(Pressupostos!K$8=1,SUM(H4:H9),"") | I10: =IF(Pressupostos!L$8=1,SUM(I4:I9),"") | J10: =IF(Pressupostos!M$8=1,SUM(J4:J9),"") | ... Q10: =IF(Pressupostos!T$8=1,SUM(Q4:Q9),"")
B11: Gastos de depreciação e de amortização | C11: =IF(Pressupostos!F$8=1,-SUM(Pressupostos!F252:F253),"") -> -33700 | D11: =IF(Pressupostos!G$8=1,-SUM(Pressupostos!G252:G253),"") -> -38200 | E11: =IF(Pressupostos!H$8=1,-SUM(Pressupostos!H252:H253),"") | F11: =IF(Pressupostos!I$8=1,-SUM(Pressupostos!I252:I253),"") | G11: =IF(Pressupostos!J$8=1,-SUM(Pressupostos!J252:J253),"") | H11: =IF(Pressupostos!K$8=1,-SUM(Pressupostos!K252:K253),"") | I11: =IF(Pressupostos!L$8=1,-SUM(Pressupostos!L252:L253),"") | J11: =IF(Pressupostos!M$8=1,-SUM(Pressupostos!M252:M253),"") | ... Q11: =IF(Pressupostos!T$8=1,-SUM(Pressupostos!T252:T253),"")
B12: EBIT | C12: =IF(Pressupostos!F$8=1,C10+C11,"") -> 76452.74 | D12: =IF(Pressupostos!G$8=1,D10+D11,"") -> 141315.79 | E12: =IF(Pressupostos!H$8=1,E10+E11,"") | F12: =IF(Pressupostos!I$8=1,F10+F11,"") | G12: =IF(Pressupostos!J$8=1,G10+G11,"") | H12: =IF(Pressupostos!K$8=1,H10+H11,"") | I12: =IF(Pressupostos!L$8=1,I10+I11,"") | J12: =IF(Pressupostos!M$8=1,J10+J11,"") | ... Q12: =IF(Pressupostos!T$8=1,Q10+Q11,"")
B13: Gastos de financiamento | C13: =IF(Pressupostos!F$8=1,-Empréstimo!F201-Empréstimo!F202,"") -> -7896.2385 | D13: =IF(Pressupostos!G$8=1,-Empréstimo!G201-Empréstimo!G202,"") -> -2524.95 | E13: =IF(Pressupostos!H$8=1,-Empréstimo!H201-Empréstimo!H202,"") | F13: =IF(Pressupostos!I$8=1,-Empréstimo!I201-Empréstimo!I202,"") | G13: =IF(Pressupostos!J$8=1,-Empréstimo!J201-Empréstimo!J202,"") | H13: =IF(Pressupostos!K$8=1,-Empréstimo!K201-Empréstimo!K202,"") | I13: =IF(Pressupostos!L$8=1,-Empréstimo!L201-Empréstimo!L202,"") | J13: =IF(Pressupostos!M$8=1,-Empréstimo!M201-Empréstimo!M202,"") | ... Q13: =IF(Pressupostos!T$8=1,-Empréstimo!T201-Empréstimo!T202,"")
B14: Resultado antes impostos | C14: =IF(Pressupostos!F$8=1,C12+C13,"") -> 68556.502 | D14: =IF(Pressupostos!G$8=1,D12+D13,"") -> 138790.84 | E14: =IF(Pressupostos!H$8=1,E12+E13,"") | F14: =IF(Pressupostos!I$8=1,F12+F13,"") | G14: =IF(Pressupostos!J$8=1,G12+G13,"") | H14: =IF(Pressupostos!K$8=1,H12+H13,"") | I14: =IF(Pressupostos!L$8=1,I12+I13,"") | J14: =IF(Pressupostos!M$8=1,J12+J13,"") | ... Q14: =IF(Pressupostos!T$8=1,Q12+Q13,"")
A15: 1 | B15: Imposto sobre o rendimento do período | C15: =IF(Pressupostos!F$8=1,-C24,"") -> -15425.213 | D15: =IF(Pressupostos!G$8=1,-D24,"") -> -31227.94 | E15: =IF(Pressupostos!H$8=1,-E24,"") | F15: =IF(Pressupostos!I$8=1,-F24,"") | G15: =IF(Pressupostos!J$8=1,-G24,"") | H15: =IF(Pressupostos!K$8=1,-H24,"") | I15: =IF(Pressupostos!L$8=1,-I24,"") | J15: =IF(Pressupostos!M$8=1,-J24,"") | ... Q15: =IF(Pressupostos!T$8=1,-Q24,"")
B16: Resultado líquido do período | C16: =IF(Pressupostos!F$8=1,C14+C15,"") -> 53131.289 | D16: =IF(Pressupostos!G$8=1,D14+D15,"") -> 107562.9 | E16: =IF(Pressupostos!H$8=1,E14+E15,"") | F16: =IF(Pressupostos!I$8=1,F14+F15,"") | G16: =IF(Pressupostos!J$8=1,G14+G15,"") | H16: =IF(Pressupostos!K$8=1,H14+H15,"") | I16: =IF(Pressupostos!L$8=1,I14+I15,"") | J16: =IF(Pressupostos!M$8=1,J14+J15,"") | ... Q16: =IF(Pressupostos!T$8=1,Q14+Q15,"")
B18: Lucro Tributável | C18: =IF(Pressupostos!F$8=1,IF(C14<0,0,C14),"") -> 68556.502 | D18: =IF(Pressupostos!G$8=1,IF(D14<0,0,D14),"") -> 138790.84 | E18: =IF(Pressupostos!H$8=1,IF(E14<0,0,E14),"") | F18: =IF(Pressupostos!I$8=1,IF(F14<0,0,F14),"") | G18: =IF(Pressupostos!J$8=1,IF(G14<0,0,G14),"") | H18: =IF(Pressupostos!K$8=1,IF(H14<0,0,H14),"") | I18: =IF(Pressupostos!L$8=1,IF(I14<0,0,I14),"") | J18: =IF(Pressupostos!M$8=1,IF(J14<0,0,J14),"") | ... Q18: =IF(Pressupostos!T$8=1,IF(Q14<0,0,Q14),"")
B19: Prejuízos Fiscais | C19: =IF(Pressupostos!F$8=1,IF(C14>0,0,C14),"") -> 0 | D19: =IF(Pressupostos!G$8=1,IF(D14>0,0,D14),"") -> 0 | E19: =IF(Pressupostos!H$8=1,IF(E14>0,0,E14),"") | F19: =IF(Pressupostos!I$8=1,IF(F14>0,0,F14),"") | G19: =IF(Pressupostos!J$8=1,IF(G14>0,0,G14),"") | H19: =IF(Pressupostos!K$8=1,IF(H14>0,0,H14),"") | I19: =IF(Pressupostos!L$8=1,IF(I14>0,0,I14),"") | J19: =IF(Pressupostos!M$8=1,IF(J14>0,0,J14),"") | ... Q19: =IF(Pressupostos!T$8=1,IF(Q14>0,0,Q14),"")
A20: 1 | B20: Prejuízos Fiscais Acumulados Dedutíveis | C20: =IF(Pressupostos!F$8=1,IF(C19>0,0,C19),"") -> 0 | D20: =IF(Pressupostos!G$8=1,IF((D19+C20+C22)>0,0,D19+C20+C22),"") -> 0 | E20: =IF(Pressupostos!H$8=1,IF((E19+D20+D22)>0,0,E19+D20+D22),"") | F20: =IF(Pressupostos!I$8=1,IF((F19+E20+E22)>0,0,F19+E20+E22),"") | G20: =IF(Pressupostos!J$8=1,IF((G19+F20+F22)>0,0,G19+F20+F22),"") | H20: =IF(Pressupostos!K$8=1,IF((H19+G20+G22)>0,0,H19+G20+G22),"") | I20: =IF(Pressupostos!L$8=1,IF((I19+H20+H22)>0,0,I19+H20+H22),"") | J20: =IF(Pressupostos!M$8=1,IF((J19+I20+I22)>0,0,J19+I20+I22),"") | K20: =IF(Pressupostos!N$8=1,IF((K19+J20+J22)>0,0,K19+J20+J22),"") | ... Q20: =IF(Pressupostos!T$8=1,IF((Q19+P20+P22)>0,0,Q19+P20+P22),"")
B21: Limite de dedução dos Prejuízos Fiscais | C21: =IF(Pressupostos!F$8=1,IF(C18>0,C18,0),"") -> 68556.502 | D21: =IF(Pressupostos!G$8=1,IF(D18>0,D18,0),"") -> 138790.84 | E21: =IF(Pressupostos!H$8=1,IF(E18>0,E18,0),"") | F21: =IF(Pressupostos!I$8=1,IF(F18>0,F18,0),"") | G21: =IF(Pressupostos!J$8=1,IF(G18>0,G18,0),"") | H21: =IF(Pressupostos!K$8=1,IF(H18>0,H18,0),"") | I21: =IF(Pressupostos!L$8=1,IF(I18>0,I18,0),"") | J21: =IF(Pressupostos!M$8=1,IF(J18>0,J18,0),"") | ... Q21: =IF(Pressupostos!T$8=1,IF(Q18>0,Q18,0),"")
B22: Prejuízos fiscais dedutíveis do período | C22: =IF(Pressupostos!F$8=1,IF(C21>0,MIN(-C20,C18),0),"") -> 0 | D22: =IF(Pressupostos!G$8=1,IF(D21>0,MIN(-D20,D18),0),"") -> 0 | E22: =IF(Pressupostos!H$8=1,IF(E21>0,MIN(-E20,E18),0),"") | F22: =IF(Pressupostos!I$8=1,IF(F21>0,MIN(-F20,F18),0),"") | G22: =IF(Pressupostos!J$8=1,IF(G21>0,MIN(-G20,G18),0),"") | H22: =IF(Pressupostos!K$8=1,IF(H21>0,MIN(-H20,H18),0),"") | I22: =IF(Pressupostos!L$8=1,IF(I21>0,MIN(-I20,I18),0),"") | J22: =IF(Pressupostos!M$8=1,IF(J21>0,MIN(-J20,J18),0),"") | ... Q22: =IF(Pressupostos!T$8=1,IF(Q21>0,MIN(-Q20,Q18),0),"")
B23: Matéria Coletável | C23: =IF(Pressupostos!F$8=1,C18-C22,"") -> 68556.502 | D23: =IF(Pressupostos!G$8=1,D18-D22,"") -> 138790.84 | E23: =IF(Pressupostos!H$8=1,E18-E22,"") | F23: =IF(Pressupostos!I$8=1,F18-F22,"") | G23: =IF(Pressupostos!J$8=1,G18-G22,"") | H23: =IF(Pressupostos!K$8=1,H18-H22,"") | I23: =IF(Pressupostos!L$8=1,I18-I22,"") | J23: =IF(Pressupostos!M$8=1,J18-J22,"") | ... Q23: =IF(Pressupostos!T$8=1,Q18-Q22,"")
B24: IRC + Derrama | C24: =IF(Pressupostos!F$8=1,C23*Pressupostos!$D$114+C18*Pressupostos!$D$115,"") -> 15425.213 | D24: =IF(Pressupostos!G$8=1,D23*Pressupostos!$D$114+D18*Pressupostos!$D$115,"") -> 31227.94 | E24: =IF(Pressupostos!H$8=1,E23*Pressupostos!$D$114+E18*Pressupostos!$D$115,"") | F24: =IF(Pressupostos!I$8=1,F23*Pressupostos!$D$114+F18*Pressupostos!$D$115,"") | G24: =IF(Pressupostos!J$8=1,G23*Pressupostos!$D$114+G18*Pressupostos!$D$115,"") | H24: =IF(Pressupostos!K$8=1,H23*Pressupostos!$D$114+H18*Pressupostos!$D$115,"") | I24: =IF(Pressupostos!L$8=1,I23*Pressupostos!$D$114+I18*Pressupostos!$D$115,"") | J24: =IF(Pressupostos!M$8=1,J23*Pressupostos!$D$114+J18*Pressupostos!$D$115,"") | ... Q24: =IF(Pressupostos!T$8=1,Q23*Pressupostos!$D$114+Q18*Pressupostos!$D$115,"")
B25: Taxa efetiva de IRC | C25: =IF(Pressupostos!F$8=1,-C15/C14,"") -> 0.225 | D25: =IF(Pressupostos!G$8=1,-D15/D14,"") -> 0.225 | E25: =IF(Pressupostos!H$8=1,-E15/E14,"") | F25: =IF(Pressupostos!I$8=1,-F15/F14,"") | G25: =IF(Pressupostos!J$8=1,-G15/G14,"") | H25: =IF(Pressupostos!K$8=1,-H15/H14,"") | I25: =IF(Pressupostos!L$8=1,-I15/I14,"") | J25: =IF(Pressupostos!M$8=1,-J15/J14,"") | ... Q25: =IF(Pressupostos!T$8=1,-Q15/Q14,"")

Sheet Empréstimo
B3: EMPRÉSTIMO BANCÁRIO DE MÉDIO E LONGO PRAZO
B5: Montante: | E5: =Pressupostos!F263 -> 173600
B6: Taxa de juro anual nominal: | E6: =Pressupostos!E266 -> 0.05
B7: Sistema de amortização | E7: Amortização através de prestações mensais, constantes e postecipadas de capital e juros
B8: Prazo | E8: =Pressupostos!F5 -> 2 | F8: anos
B9: Custos de emissão (em % do empréstimo) | E9: =Pressupostos!E268 -> 0.005
B10: Taxa de imposto de selo sobre os juros | E10: =Pressupostos!E269 -> 0.04
B11: Prestação mensal | E11: =PMT(E6/12,E8*12,-E5,0,0) -> 7616.0733
B13: Mês | C13: Data | D13: Capital em dívida | E13: Juros | F13: Reembolso | G13: Prestação | H13: Outras despesas | I13: Economia fiscal | J13: Cash-flow | L13: Taxa de IRC EIetiva
B14: 0 | C14: =DATE(Pressupostos!F4-1,12,31) -> 45291 | D14: =E5 -> 173600 | H14: =E5*E9 -> 868 | J14: =IF(ISNUMBER(B15)=TRUE,D14-G14-H14+I14,"") -> 172732
B15: =IF(B14<>"",IF(B14+1<=E$8*12,B14+1,""),"") -> 1 | C15: =IF(ISNUMBER(B15)=TRUE,EOMONTH(C14,1),"") -> 45322 | D15: =IF(ISNUMBER(B15)=TRUE,D14-F14,"") -> 173600 | E15: =IF(ISNUMBER(B15)=TRUE,D15*$E$6/12,"") -> 723.33333 | F15: =IF(ISNUMBER(B15)=TRUE,G15-E15,"") -> 6892.7399 | G15: =IF(ISNUMBER(B15)=TRUE,$E$11,"") -> 7616.0733 | H15: =IF(ISNUMBER(B15)=TRUE,E15*$E$10,"") -> 28.933333 | I15: =IF(ISNUMBER(B15)=TRUE,(E15+H15+$H$14/($E$8*12))*L15,"") -> 177.3975 | J15: =IF(ISNUMBER(B15)=TRUE,-G15-H15+I15,"") -> -7467.6091 | L15: =IF(ISNUMBER(B15)=TRUE,DR!C$25,"") -> 0.225
B16: =IF(B15<>"",IF(B15+1<=E$8*12,B15+1,""),"") -> 2 | C16: =IF(ISNUMBER(B16)=TRUE,EOMONTH(C15,1),"") -> 45351 | D16: =IF(ISNUMBER(B16)=TRUE,D15-F15,"") -> 166707.26 | E16: =IF(ISNUMBER(B16)=TRUE,D16*$E$6/12,"") -> 694.61358 | F16: =IF(ISNUMBER(B16)=TRUE,G16-E16,"") -> 6921.4597 | G16: =IF(ISNUMBER(B16)=TRUE,$E$11,"") -> 7616.0733 | H16: =IF(ISNUMBER(B16)=TRUE,E16*$E$10,"") -> 27.784543 | I16: =IF(ISNUMBER(B16)=TRUE,(E16+H16+$H$14/($E$8*12))*L16,"") -> 170.67708 | J16: =IF(ISNUMBER(B16)=TRUE,-G16-H16+I16,"") -> -7473.1807 | L16: =IF(ISNUMBER(B16)=TRUE,DR!C$25,"") -> 0.225
B17: =IF(B16<>"",IF(B16+1<=E$8*12,B16+1,""),"") -> 3 | C17: =IF(ISNUMBER(B17)=TRUE,EOMONTH(C16,1),"") -> 45382 | D17: =IF(ISNUMBER(B17)=TRUE,D16-F16,"") -> 159785.8 | E17: =IF(ISNUMBER(B17)=TRUE,D17*$E$6/12,"") -> 665.77417 | F17: =IF(ISNUMBER(B17)=TRUE,G17-E17,"") -> 6950.2991 | G17: =IF(ISNUMBER(B17)=TRUE,$E$11,"") -> 7616.0733 | H17: =IF(ISNUMBER(B17)=TRUE,E17*$E$10,"") -> 26.630967 | I17: =IF(ISNUMBER(B17)=TRUE,(E17+H17+$H$14/($E$8*12))*L17,"") -> 163.92866 | J17: =IF(ISNUMBER(B17)=TRUE,-G17-H17+I17,"") -> -7478.7756 | L17: =IF(ISNUMBER(B17)=TRUE,DR!C$25,"") -> 0.225
B18: =IF(B17<>"",IF(B17+1<=E$8*12,B17+1,""),"") -> 4 | C18: =IF(ISNUMBER(B18)=TRUE,EOMONTH(C17,1),"") -> 45412 | D18: =IF(ISNUMBER(B18)=TRUE,D17-F17,"") -> 152835.5 | E18: =IF(ISNUMBER(B18)=TRUE,D18*$E$6/12,"") -> 636.81459 | F18: =IF(ISNUMBER(B18)=TRUE,G18-E18,"") -> 6979.2587 | G18: =IF(ISNUMBER(B18)=TRUE,$E$11,"") -> 7616.0733 | H18: =IF(ISNUMBER(B18)=TRUE,E18*$E$10,"") -> 25.472584 | I18: =IF(ISNUMBER(B18)=TRUE,(E18+H18+$H$14/($E$8*12))*L18,"") -> 157.15211 | J18: =IF(ISNUMBER(B18)=TRUE,-G18-H18+I18,"") -> -7484.3937 | L18: =IF(ISNUMBER(B18)=TRUE,DR!C$25,"") -> 0.225
B19: =IF(B18<>"",IF(B18+1<=E$8*12,B18+1,""),"") -> 5 | C19: =IF(ISNUMBER(B19)=TRUE,EOMONTH(C18,1),"") -> 45443 | D19: =IF(ISNUMBER(B19)=TRUE,D18-F18,"") -> 145856.24 | E19: =IF(ISNUMBER(B19)=TRUE,D19*$E$6/12,"") -> 607.73434 | F19: =IF(ISNUMBER(B19)=TRUE,G19-E19,"") -> 7008.3389 | G19: =IF(ISNUMBER(B19)=TRUE,$E$11,"") -> 7616.0733 | H19: =IF(ISNUMBER(B19)=TRUE,E19*$E$10,"") -> 24.309374 | I19: =IF(ISNUMBER(B19)=TRUE,(E19+H19+$H$14/($E$8*12))*L19,"") -> 150.34734 | J19: =IF(ISNUMBER(B19)=TRUE,-G19-H19+I19,"") -> -7490.0353 | L19: =IF(ISNUMBER(B19)=TRUE,DR!C$25,"") -> 0.225
B20: =IF(B19<>"",IF(B19+1<=E$8*12,B19+1,""),"") -> 6 | C20: =IF(ISNUMBER(B20)=TRUE,EOMONTH(C19,1),"") -> 45473 | D20: =IF(ISNUMBER(B20)=TRUE,D19-F19,"") -> 138847.9 | E20: =IF(ISNUMBER(B20)=TRUE,D20*$E$6/12,"") -> 578.53293 | F20: =IF(ISNUMBER(B20)=TRUE,G20-E20,"") -> 7037.5403 | G20: =IF(ISNUMBER(B20)=TRUE,$E$11,"") -> 7616.0733 | H20: =IF(ISNUMBER(B20)=TRUE,E20*$E$10,"") -> 23.141317 | I20: =IF(ISNUMBER(B20)=TRUE,(E20+H20+$H$14/($E$8*12))*L20,"") -> 143.51421 | J20: =IF(ISNUMBER(B20)=TRUE,-G20-H20+I20,"") -> -7495.7004 | L20: =IF(ISNUMBER(B20)=TRUE,DR!C$25,"") -> 0.225
B21: =IF(B20<>"",IF(B20+1<=E$8*12,B20+1,""),"") -> 7 | C21: =IF(ISNUMBER(B21)=TRUE,EOMONTH(C20,1),"") -> 45504 | D21: =IF(ISNUMBER(B21)=TRUE,D20-F20,"") -> 131810.36 | E21: =IF(ISNUMBER(B21)=TRUE,D21*$E$6/12,"") -> 549.20985 | F21: =IF(ISNUMBER(B21)=TRUE,G21-E21,"") -> 7066.8634 | G21: =IF(ISNUMBER(B21)=TRUE,$E$11,"") -> 7616.0733 | H21: =IF(ISNUMBER(B21)=TRUE,E21*$E$10,"") -> 21.968394 | I21: =IF(ISNUMBER(B21)=TRUE,(E21+H21+$H$14/($E$8*12))*L21,"") -> 136.6526 | J21: =IF(ISNUMBER(B21)=TRUE,-G21-H21+I21,"") -> -7501.389 | L21: =IF(ISNUMBER(B21)=TRUE,DR!C$25,"") -> 0.225
B22: =IF(B21<>"",IF(B21+1<=E$8*12,B21+1,""),"") -> 8 | C22: =IF(ISNUMBER(B22)=TRUE,EOMONTH(C21,1),"") -> 45535 | D22: =IF(ISNUMBER(B22)=TRUE,D21-F21,"") -> 124743.5 | E22: =IF(ISNUMBER(B22)=TRUE,D22*$E$6/12,"") -> 519.76458 | F22: =IF(ISNUMBER(B22)=TRUE,G22-E22,"") -> 7096.3087 | G22: =IF(ISNUMBER(B22)=TRUE,$E$11,"") -> 7616.0733 | H22: =IF(ISNUMBER(B22)=TRUE,E22*$E$10,"") -> 20.790583 | I22: =IF(ISNUMBER(B22)=TRUE,(E22+H22+$H$14/($E$8*12))*L22,"") -> 129.76241 | J22: =IF(ISNUMBER(B22)=TRUE,-G22-H22+I22,"") -> -7507.1014 | L22: =IF(ISNUMBER(B22)=TRUE,DR!C$25,"") -> 0.225
B23: =IF(B22<>"",IF(B22+1<=E$8*12,B22+1,""),"") -> 9 | C23: =IF(ISNUMBER(B23)=TRUE,EOMONTH(C22,1),"") -> 45565 | D23: =IF(ISNUMBER(B23)=TRUE,D22-F22,"") -> 117647.19 | E23: =IF(ISNUMBER(B23)=TRUE,D23*$E$6/12,"") -> 490.19663 | F23: =IF(ISNUMBER(B23)=TRUE,G23-E23,"") -> 7125.8766 | G23: =IF(ISNUMBER(B23)=TRUE,$E$11,"") -> 7616.0733 | H23: =IF(ISNUMBER(B23)=TRUE,E23*$E$10,"") -> 19.607865 | I23: =IF(ISNUMBER(B23)=TRUE,(E23+H23+$H$14/($E$8*12))*L23,"") -> 122.84351 | J23: =IF(ISNUMBER(B23)=TRUE,-G23-H23+I23,"") -> -7512.8376 | L23: =IF(ISNUMBER(B23)=TRUE,DR!C$25,"") -> 0.225
B24: =IF(B23<>"",IF(B23+1<=E$8*12,B23+1,""),"") -> 10 | C24: =IF(ISNUMBER(B24)=TRUE,EOMONTH(C23,1),"") -> 45596 | D24: =IF(ISNUMBER(B24)=TRUE,D23-F23,"") -> 110521.31 | E24: =IF(ISNUMBER(B24)=TRUE,D24*$E$6/12,"") -> 460.50548 | F24: =IF(ISNUMBER(B24)=TRUE,G24-E24,"") -> 7155.5678 | G24: =IF(ISNUMBER(B24)=TRUE,$E$11,"") -> 7616.0733 | H24: =IF(ISNUMBER(B24)=TRUE,E24*$E$10,"") -> 18.420219 | I24: =IF(ISNUMBER(B24)=TRUE,(E24+H24+$H$14/($E$8*12))*L24,"") -> 115.89578 | J24: =IF(ISNUMBER(B24)=TRUE,-G24-H24+I24,"") -> -7518.5977 | L24: =IF(ISNUMBER(B24)=TRUE,DR!C$25,"") -> 0.225
B25: =IF(B24<>"",IF(B24+1<=E$8*12,B24+1,""),"") -> 11 | C25: =IF(ISNUMBER(B25)=TRUE,EOMONTH(C24,1),"") -> 45626 | D25: =IF(ISNUMBER(B25)=TRUE,D24-F24,"") -> 103365.75 | E25: =IF(ISNUMBER(B25)=TRUE,D25*$E$6/12,"") -> 430.69061 | F25: =IF(ISNUMBER(B25)=TRUE,G25-E25,"") -> 7185.3826 | G25: =IF(ISNUMBER(B25)=TRUE,$E$11,"") -> 7616.0733 | H25: =IF(ISNUMBER(B25)=TRUE,E25*$E$10,"") -> 17.227624 | I25: =IF(ISNUMBER(B25)=TRUE,(E25+H25+$H$14/($E$8*12))*L25,"") -> 108.9191 | J25: =IF(ISNUMBER(B25)=TRUE,-G25-H25+I25,"") -> -7524.3818 | L25: =IF(ISNUMBER(B25)=TRUE,DR!C$25,"") -> 0.225
B26: =IF(B25<>"",IF(B25+1<=E$8*12,B25+1,""),"") -> 12 | C26: =IF(ISNUMBER(B26)=TRUE,EOMONTH(C25,1),"") -> 45657 | D26: =IF(ISNUMBER(B26)=TRUE,D25-F25,"") -> 96180.364 | E26: =IF(ISNUMBER(B26)=TRUE,D26*$E$6/12,"") -> 400.75152 | F26: =IF(ISNUMBER(B26)=TRUE,G26-E26,"") -> 7215.3217 | G26: =IF(ISNUMBER(B26)=TRUE,$E$11,"") -> 7616.0733 | H26: =IF(ISNUMBER(B26)=TRUE,E26*$E$10,"") -> 16.030061 | I26: =IF(ISNUMBER(B26)=TRUE,(E26+H26+$H$14/($E$8*12))*L26,"") -> 101.91336 | J26: =IF(ISNUMBER(B26)=TRUE,-G26-H26+I26,"") -> -7530.19 | L26: =IF(ISNUMBER(B26)=TRUE,DR!C$25,"") -> 0.225
B27: =IF(B26<>"",IF(B26+1<=E$8*12,B26+1,""),"") -> 13 | C27: =IF(ISNUMBER(B27)=TRUE,EOMONTH(C26,1),"") -> 45688 | D27: =IF(ISNUMBER(B27)=TRUE,D26-F26,"") -> 88965.043 | E27: =IF(ISNUMBER(B27)=TRUE,D27*$E$6/12,"") -> 370.68768 | F27: =IF(ISNUMBER(B27)=TRUE,G27-E27,"") -> 7245.3856 | G27: =IF(ISNUMBER(B27)=TRUE,$E$11,"") -> 7616.0733 | H27: =IF(ISNUMBER(B27)=TRUE,E27*$E$10,"") -> 14.827507 | I27: =IF(ISNUMBER(B27)=TRUE,(E27+H27+$H$14/($E$8*12))*L27,"") -> 94.878416 | J27: =IF(ISNUMBER(B27)=TRUE,-G27-H27+I27,"") -> -7536.0223 | L27: =IF(ISNUMBER(B27)=TRUE,DR!D$25,"") -> 0.225
B28: =IF(B27<>"",IF(B27+1<=E$8*12,B27+1,""),"") -> 14 | C28: =IF(ISNUMBER(B28)=TRUE,EOMONTH(C27,1),"") -> 45716 | D28: =IF(ISNUMBER(B28)=TRUE,D27-F27,"") -> 81719.657 | E28: =IF(ISNUMBER(B28)=TRUE,D28*$E$6/12,"") -> 340.49857 | F28: =IF(ISNUMBER(B28)=TRUE,G28-E28,"") -> 7275.5747 | G28: =IF(ISNUMBER(B28)=TRUE,$E$11,"") -> 7616.0733 | H28: =IF(ISNUMBER(B28)=TRUE,E28*$E$10,"") -> 13.619943 | I28: =IF(ISNUMBER(B28)=TRUE,(E28+H28+$H$14/($E$8*12))*L28,"") -> 87.814166 | J28: =IF(ISNUMBER(B28)=TRUE,-G28-H28+I28,"") -> -7541.879 | L28: =IF(ISNUMBER(B28)=TRUE,DR!D$25,"") -> 0.225
B29: =IF(B28<>"",IF(B28+1<=E$8*12,B28+1,""),"") -> 15 | C29: =IF(ISNUMBER(B29)=TRUE,EOMONTH(C28,1),"") -> 45747 | D29: =IF(ISNUMBER(B29)=TRUE,D28-F28,"") -> 74444.082 | E29: =IF(ISNUMBER(B29)=TRUE,D29*$E$6/12,"") -> 310.18368 | F29: =IF(ISNUMBER(B29)=TRUE,G29-E29,"") -> 7305.8896 | G29: =IF(ISNUMBER(B29)=TRUE,$E$11,"") -> 7616.0733 | H29: =IF(ISNUMBER(B29)=TRUE,E29*$E$10,"") -> 12.407347 | I29: =IF(ISNUMBER(B29)=TRUE,(E29+H29+$H$14/($E$8*12))*L29,"") -> 80.72048 | J29: =IF(ISNUMBER(B29)=TRUE,-G29-H29+I29,"") -> -7547.7601 | L29: =IF(ISNUMBER(B29)=TRUE,DR!D$25,"") -> 0.225
B30: =IF(B29<>"",IF(B29+1<=E$8*12,B29+1,""),"") -> 16 | C30: =IF(ISNUMBER(B30)=TRUE,EOMONTH(C29,1),"") -> 45777 | D30: =IF(ISNUMBER(B30)=TRUE,D29-F29,"") -> 67138.193 | E30: =IF(ISNUMBER(B30)=TRUE,D30*$E$6/12,"") -> 279.74247 | F30: =IF(ISNUMBER(B30)=TRUE,G30-E30,"") -> 7336.3308 | G30: =IF(ISNUMBER(B30)=TRUE,$E$11,"") -> 7616.0733 | H30: =IF(ISNUMBER(B30)=TRUE,E30*$E$10,"") -> 11.189699 | I30: =IF(ISNUMBER(B30)=TRUE,(E30+H30+$H$14/($E$8*12))*L30,"") -> 73.597238 | J30: =IF(ISNUMBER(B30)=TRUE,-G30-H30+I30,"") -> -7553.6657 | L30: =IF(ISNUMBER(B30)=TRUE,DR!D$25,"") -> 0.225
B31: =IF(B30<>"",IF(B30+1<=E$8*12,B30+1,""),"") -> 17 | C31: =IF(ISNUMBER(B31)=TRUE,EOMONTH(C30,1),"") -> 45808 | D31: =IF(ISNUMBER(B31)=TRUE,D30-F30,"") -> 59801.862 | E31: =IF(ISNUMBER(B31)=TRUE,D31*$E$6/12,"") -> 249.17442 | F31: =IF(ISNUMBER(B31)=TRUE,G31-E31,"") -> 7366.8988 | G31: =IF(ISNUMBER(B31)=TRUE,$E$11,"") -> 7616.0733 | H31: =IF(ISNUMBER(B31)=TRUE,E31*$E$10,"") -> 9.966977 | I31: =IF(ISNUMBER(B31)=TRUE,(E31+H31+$H$14/($E$8*12))*L31,"") -> 66.444315 | J31: =IF(ISNUMBER(B31)=TRUE,-G31-H31+I31,"") -> -7559.5959 | L31: =IF(ISNUMBER(B31)=TRUE,DR!D$25,"") -> 0.225
B32: =IF(B31<>"",IF(B31+1<=E$8*12,B31+1,""),"") -> 18 | C32: =IF(ISNUMBER(B32)=TRUE,EOMONTH(C31,1),"") -> 45838 | D32: =IF(ISNUMBER(B32)=TRUE,D31-F31,"") -> 52434.963 | E32: =IF(ISNUMBER(B32)=TRUE,D32*$E$6/12,"") -> 218.47901 | F32: =IF(ISNUMBER(B32)=TRUE,G32-E32,"") -> 7397.5942 | G32: =IF(ISNUMBER(B32)=TRUE,$E$11,"") -> 7616.0733 | H32: =IF(ISNUMBER(B32)=TRUE,E32*$E$10,"") -> 8.7391605 | I32: =IF(ISNUMBER(B32)=TRUE,(E32+H32+$H$14/($E$8*12))*L32,"") -> 59.261589 | J32: =IF(ISNUMBER(B32)=TRUE,-G32-H32+I32,"") -> -7565.5508 | L32: =IF(ISNUMBER(B32)=TRUE,DR!D$25,"") -> 0.225
B33: =IF(B32<>"",IF(B32+1<=E$8*12,B32+1,""),"") -> 19 | C33: =IF(ISNUMBER(B33)=TRUE,EOMONTH(C32,1),"") -> 45869 | D33: =IF(ISNUMBER(B33)=TRUE,D32-F32,"") -> 45037.369 | E33: =IF(ISNUMBER(B33)=TRUE,D33*$E$6/12,"") -> 187.6557 | F33: =IF(ISNUMBER(B33)=TRUE,G33-E33,"") -> 7428.4176 | G33: =IF(ISNUMBER(B33)=TRUE,$E$11,"") -> 7616.0733 | H33: =IF(ISNUMBER(B33)=TRUE,E33*$E$10,"") -> 7.5062281 | I33: =IF(ISNUMBER(B33)=TRUE,(E33+H33+$H$14/($E$8*12))*L33,"") -> 52.048935 | J33: =IF(ISNUMBER(B33)=TRUE,-G33-H33+I33,"") -> -7571.5306 | L33: =IF(ISNUMBER(B33)=TRUE,DR!D$25,"") -> 0.225
B34: =IF(B33<>"",IF(B33+1<=E$8*12,B33+1,""),"") -> 20 | C34: =IF(ISNUMBER(B34)=TRUE,EOMONTH(C33,1),"") -> 45900 | D34: =IF(ISNUMBER(B34)=TRUE,D33-F33,"") -> 37608.951 | E34: =IF(ISNUMBER(B34)=TRUE,D34*$E$6/12,"") -> 156.70396 | F34: =IF(ISNUMBER(B34)=TRUE,G34-E34,"") -> 7459.3693 | G34: =IF(ISNUMBER(B34)=TRUE,$E$11,"") -> 7616.0733 | H34: =IF(ISNUMBER(B34)=TRUE,E34*$E$10,"") -> 6.2681585 | I34: =IF(ISNUMBER(B34)=TRUE,(E34+H34+$H$14/($E$8*12))*L34,"") -> 44.806227 | J34: =IF(ISNUMBER(B34)=TRUE,-G34-H34+I34,"") -> -7577.5352 | L34: =IF(ISNUMBER(B34)=TRUE,DR!D$25,"") -> 0.225
B35: =IF(B34<>"",IF(B34+1<=E$8*12,B34+1,""),"") -> 21 | C35: =IF(ISNUMBER(B35)=TRUE,EOMONTH(C34,1),"") -> 45930 | D35: =IF(ISNUMBER(B35)=TRUE,D34-F34,"") -> 30149.582 | E35: =IF(ISNUMBER(B35)=TRUE,D35*$E$6/12,"") -> 125.62326 | F35: =IF(ISNUMBER(B35)=TRUE,G35-E35,"") -> 7490.45 | G35: =IF(ISNUMBER(B35)=TRUE,$E$11,"") -> 7616.0733 | H35: =IF(ISNUMBER(B35)=TRUE,E35*$E$10,"") -> 5.0249303 | I35: =IF(ISNUMBER(B35)=TRUE,(E35+H35+$H$14/($E$8*12))*L35,"") -> 37.533342 | J35: =IF(ISNUMBER(B35)=TRUE,-G35-H35+I35,"") -> -7583.5648 | L35: =IF(ISNUMBER(B35)=TRUE,DR!D$25,"") -> 0.225
B36: =IF(B35<>"",IF(B35+1<=E$8*12,B35+1,""),"") -> 22 | C36: =IF(ISNUMBER(B36)=TRUE,EOMONTH(C35,1),"") -> 45961 | D36: =IF(ISNUMBER(B36)=TRUE,D35-F35,"") -> 22659.132 | E36: =IF(ISNUMBER(B36)=TRUE,D36*$E$6/12,"") -> 94.41305 | F36: =IF(ISNUMBER(B36)=TRUE,G36-E36,"") -> 7521.6602 | G36: =IF(ISNUMBER(B36)=TRUE,$E$11,"") -> 7616.0733 | H36: =IF(ISNUMBER(B36)=TRUE,E36*$E$10,"") -> 3.776522 | I36: =IF(ISNUMBER(B36)=TRUE,(E36+H36+$H$14/($E$8*12))*L36,"") -> 30.230154 | J36: =IF(ISNUMBER(B36)=TRUE,-G36-H36+I36,"") -> -7589.6196 | L36: =IF(ISNUMBER(B36)=TRUE,DR!D$25,"") -> 0.225
B37: =IF(B36<>"",IF(B36+1<=E$8*12,B36+1,""),"") -> 23 | C37: =IF(ISNUMBER(B37)=TRUE,EOMONTH(C36,1),"") -> 45991 | D37: =IF(ISNUMBER(B37)=TRUE,D36-F36,"") -> 15137.472 | E37: =IF(ISNUMBER(B37)=TRUE,D37*$E$6/12,"") -> 63.072799 | F37: =IF(ISNUMBER(B37)=TRUE,G37-E37,"") -> 7553.0005 | G37: =IF(ISNUMBER(B37)=TRUE,$E$11,"") -> 7616.0733 | H37: =IF(ISNUMBER(B37)=TRUE,E37*$E$10,"") -> 2.522912 | I37: =IF(ISNUMBER(B37)=TRUE,(E37+H37+$H$14/($E$8*12))*L37,"") -> 22.896535 | J37: =IF(ISNUMBER(B37)=TRUE,-G37-H37+I37,"") -> -7595.6996 | L37: =IF(ISNUMBER(B37)=TRUE,DR!D$25,"") -> 0.225
B38: =IF(B37<>"",IF(B37+1<=E$8*12,B37+1,""),"") -> 24 | C38: =IF(ISNUMBER(B38)=TRUE,EOMONTH(C37,1),"") -> 46022 | D38: =IF(ISNUMBER(B38)=TRUE,D37-F37,"") -> 7584.4713 | E38: =IF(ISNUMBER(B38)=TRUE,D38*$E$6/12,"") -> 31.601964 | F38: =IF(ISNUMBER(B38)=TRUE,G38-E38,"") -> 7584.4713 | G38: =IF(ISNUMBER(B38)=TRUE,$E$11,"") -> 7616.0733 | H38: =IF(ISNUMBER(B38)=TRUE,E38*$E$10,"") -> 1.2640785 | I38: =IF(ISNUMBER(B38)=TRUE,(E38+H38+$H$14/($E$8*12))*L38,"") -> 15.53236 | J38: =IF(ISNUMBER(B38)=TRUE,-G38-H38+I38,"") -> -7601.805 | L38: =IF(ISNUMBER(B38)=TRUE,DR!D$25,"") -> 0.225
B39: =IF(B38<>"",IF(B38+1<=E$8*12,B38+1,""),"") | C39: =IF(ISNUMBER(B39)=TRUE,EOMONTH(C38,1),"") | D39: =IF(ISNUMBER(B39)=TRUE,D38-F38,"") | E39: =IF(ISNUMBER(B39)=TRUE,D39*$E$6/12,"") | F39: =IF(ISNUMBER(B39)=TRUE,G39-E39,"") | G39: =IF(ISNUMBER(B39)=TRUE,$E$11,"") | H39: =IF(ISNUMBER(B39)=TRUE,E39*$E$10,"") | I39: =IF(ISNUMBER(B39)=TRUE,(E39+H39+$H$14/($E$8*12))*L39,"") | J39: =IF(ISNUMBER(B39)=TRUE,-G39-H39+I39,"") | L39: =IF(ISNUMBER(B39)=TRUE,DR!E$25,"")
B40: =IF(B39<>"",IF(B39+1<=E$8*12,B39+1,""),"") | C40: =IF(ISNUMBER(B40)=TRUE,EOMONTH(C39,1),"") | D40: =IF(ISNUMBER(B40)=TRUE,D39-F39,"") | E40: =IF(ISNUMBER(B40)=TRUE,D40*$E$6/12,"") | F40: =IF(ISNUMBER(B40)=TRUE,G40-E40,"") | G40: =IF(ISNUMBER(B40)=TRUE,$E$11,"") | H40: =IF(ISNUMBER(B40)=TRUE,E40*$E$10,"") | I40: =IF(ISNUMBER(B40)=TRUE,(E40+H40+$H$14/($E$8*12))*L40,"") | J40: =IF(ISNUMBER(B40)=TRUE,-G40-H40+I40,"") | L40: =IF(ISNUMBER(B40)=TRUE,DR!E$25,"")
B41: =IF(B40<>"",IF(B40+1<=E$8*12,B40+1,""),"") | C41: =IF(ISNUMBER(B41)=TRUE,EOMONTH(C40,1),"") | D41: =IF(ISNUMBER(B41)=TRUE,D40-F40,"") | E41: =IF(ISNUMBER(B41)=TRUE,D41*$E$6/12,"") | F41: =IF(ISNUMBER(B41)=TRUE,G41-E41,"") | G41: =IF(ISNUMBER(B41)=TRUE,$E$11,"") | H41: =IF(ISNUMBER(B41)=TRUE,E41*$E$10,"") | I41: =IF(ISNUMBER(B41)=TRUE,(E41+H41+$H$14/($E$8*12))*L41,"") | J41: =IF(ISNUMBER(B41)=TRUE,-G41-H41+I41,"") | L41: =IF(ISNUMBER(B41)=TRUE,DR!E$25,"")
B42: =IF(B41<>"",IF(B41+1<=E$8*12,B41+1,""),"") | C42: =IF(ISNUMBER(B42)=TRUE,EOMONTH(C41,1),"") | D42: =IF(ISNUMBER(B42)=TRUE,D41-F41,"") | E42: =IF(ISNUMBER(B42)=TRUE,D42*$E$6/12,"") | F42: =IF(ISNUMBER(B42)=TRUE,G42-E42,"") | G42: =IF(ISNUMBER(B42)=TRUE,$E$11,"") | H42: =IF(ISNUMBER(B42)=TRUE,E42*$E$10,"") | I42: =IF(ISNUMBER(B42)=TRUE,(E42+H42+$H$14/($E$8*12))*L42,"") | J42: =IF(ISNUMBER(B42)=TRUE,-G42-H42+I42,"") | L42: =IF(ISNUMBER(B42)=TRUE,DR!E$25,"")
B43: =IF(B42<>"",IF(B42+1<=E$8*12,B42+1,""),"") | C43: =IF(ISNUMBER(B43)=TRUE,EOMONTH(C42,1),"") | D43: =IF(ISNUMBER(B43)=TRUE,D42-F42,"") | E43: =IF(ISNUMBER(B43)=TRUE,D43*$E$6/12,"") | F43: =IF(ISNUMBER(B43)=TRUE,G43-E43,"") | G43: =IF(ISNUMBER(B43)=TRUE,$E$11,"") | H43: =IF(ISNUMBER(B43)=TRUE,E43*$E$10,"") | I43: =IF(ISNUMBER(B43)=TRUE,(E43+H43+$H$14/($E$8*12))*L43,"") | J43: =IF(ISNUMBER(B43)=TRUE,-G43-H43+I43,"") | L43: =IF(ISNUMBER(B43)=TRUE,DR!E$25,"")
B44: =IF(B43<>"",IF(B43+1<=E$8*12,B43+1,""),"") | C44: =IF(ISNUMBER(B44)=TRUE,EOMONTH(C43,1),"") | D44: =IF(ISNUMBER(B44)=TRUE,D43-F43,"") | E44: =IF(ISNUMBER(B44)=TRUE,D44*$E$6/12,"") | F44: =IF(ISNUMBER(B44)=TRUE,G44-E44,"") | G44: =IF(ISNUMBER(B44)=TRUE,$E$11,"") | H44: =IF(ISNUMBER(B44)=TRUE,E44*$E$10,"") | I44: =IF(ISNUMBER(B44)=TRUE,(E44+H44+$H$14/($E$8*12))*L44,"") | J44: =IF(ISNUMBER(B44)=TRUE,-G44-H44+I44,"") | L44: =IF(ISNUMBER(B44)=TRUE,DR!E$25,"")
...

Sheet NFM
B2: ESTADO E OUTROS ENTES PÚBLICOS
B3: Descrição | C3: =IF(Pressupostos!F$10<>"",Pressupostos!F$10-1,"") -> 2023 | D3: =IF(Pressupostos!F$10<>"",Pressupostos!F$10,"") -> 2024 | E3: =IF(Pressupostos!G$10<>"",Pressupostos!G$10,"") -> 2025 | F3: =IF(Pressupostos!H$10<>"",Pressupostos!H$10,"") | G3: =IF(Pressupostos!I$10<>"",Pressupostos!I$10,"") | H3: =IF(Pressupostos!J$10<>"",Pressupostos!J$10,"") | I3: =IF(Pressupostos!K$10<>"",Pressupostos!K$10,"") | J3: =IF(Pressupostos!L$10<>"",Pressupostos!L$10,"") | K3: =IF(Pressupostos!M$10<>"",Pressupostos!M$10,"") | ... R3: =IF(Pressupostos!T$10<>"",Pressupostos!T$10,"")
B4: Imposto sobre o valor acrescentado:
